Workbook

Sheet Risk Register
A1: NovaTech Solutions: Risk reyestri (ISO/IEC 27001:2022, bənd 6.1.2)
A2: Göy mətnli xanalar (E, F, L, M və mətn sütunları) sizin daxil etdiyiniz məlumatdır. Bal, Səviyyə və qalıq hesablamaları avtomatikdir. Yeni risk əlavə etmək üçün növbəti boş sətri doldurun (maksimum 30 sətir).
A3: Formula: Bal = Ehtimal × Təsir. 1-4 Aşağı, 5-9 Orta, 10-16 Yüksək, 17-25 Kritik. Qalıq risk (L-O) Faza 8-də, nəzarətlər tətbiq olunandan sonra doldurulur.
A4: ID | B4: Aktiv | C4: Təhdid | D4: Zəiflik | E4: Ehtimal (1-5) | F4: Təsir (1-5) | G4: Bal | H4: Səviyyə | I4: Müalicə | J4: Nəzarət (Annex A) | K4: Faza | L4: Qalıq ehtimal | M4: Qalıq təsir | N4: Qalıq bal | O4: Qalıq səviyyə
A5: R01 | B5: A04 AWS hesabı və IAM | C5: Hesabın ələ keçirilməsi | D5: MFA yoxdur, zəif parollar | E5: 4 | F5: 5 | G5: =IF(OR(E5="",F5=""),"",E5*F5) -> 20 | H5: =IF(G5="","",IF(G5>=17,"Kritik",IF(G5>=10,"Yüksək",IF(G5>=5,"Orta","Aşağı")))) -> Kritik | I5: Azaltmaq | J5: 5.17, 8.5, 8.2 | K5: 4 | N5: =IF(OR(L5="",M5=""),"",L5*M5) | O5: =IF(N5="","",IF(N5>=17,"Kritik",IF(N5>=10,"Yüksək",IF(N5>=5,"Orta","Aşağı"))))
A6: R02 | B6: A01 Müştəri məlumatları | C6: Təsadüfən açıq saxlanma | D6: Səhv konfiqurasiya olunmuş S3 | E6: 3 | F6: 5 | G6: =IF(OR(E6="",F6=""),"",E6*F6) -> 15 | H6: =IF(G6="","",IF(G6>=17,"Kritik",IF(G6>=10,"Yüksək",IF(G6>=5,"Orta","Aşağı")))) -> Yüksək | I6: Azaltmaq | J6: 8.3, 5.23, 8.9 | K6: 3, 4 | N6: =IF(OR(L6="",M6=""),"",L6*M6) | O6: =IF(N6="","",IF(N6>=17,"Kritik",IF(N6>=10,"Yüksək",IF(N6>=5,"Orta","Aşağı"))))
A7: R03 | B7: A01 Müştəri məlumatları | C7: Məlumatın oğurlanması | D7: Saxlama zamanı şifrələmə yoxdur | E7: 3 | F7: 4 | G7: =IF(OR(E7="",F7=""),"",E7*F7) -> 12 | H7: =IF(G7="","",IF(G7>=17,"Kritik",IF(G7>=10,"Yüksək",IF(G7>=5,"Orta","Aşağı")))) -> Yüksək | I7: Azaltmaq | J7: 8.24 | K7: 6, 7 | N7: =IF(OR(L7="",M7=""),"",L7*M7) | O7: =IF(N7="","",IF(N7>=17,"Kritik",IF(N7>=10,"Yüksək",IF(N7>=5,"Orta","Aşağı"))))
A8: R04 | B8: A03 Veb server | C8: Brute-force hücumu | D8: SSH hamıya açıqdır (0.0.0.0/0) | E8: 4 | F8: 4 | G8: =IF(OR(E8="",F8=""),"",E8*F8) -> 16 | H8: =IF(G8="","",IF(G8>=17,"Kritik",IF(G8>=10,"Yüksək",IF(G8>=5,"Orta","Aşağı")))) -> Yüksək | I8: Azaltmaq | J8: 8.20, 8.22 | K8: 4 | N8: =IF(OR(L8="",M8=""),"",L8*M8) | O8: =IF(N8="","",IF(N8>=17,"Kritik",IF(N8>=10,"Yüksək",IF(N8>=5,"Orta","Aşağı"))))
A9: R05 | B9: A07 Loqlar | C9: Hücumun aşkarlanmaması | D9: Mərkəzləşdirilmiş loqlama yoxdur | E9: 4 | F9: 4 | G9: =IF(OR(E9="",F9=""),"",E9*F9) -> 16 | H9: =IF(G9="","",IF(G9>=17,"Kritik",IF(G9>=10,"Yüksək",IF(G9>=5,"Orta","Aşağı")))) -> Yüksək | I9: Azaltmaq | J9: 8.15, 8.16 | K9: 5 | N9: =IF(OR(L9="",M9=""),"",L9*M9) | O9: =IF(N9="","",IF(N9>=17,"Kritik",IF(N9>=10,"Yüksək",IF(N9>=5,"Orta","Aşağı"))))
A10: R06 | B10: A02 Mənbə kodu | C10: Gizli məlumatın sızması | D10: Kodda sərt yazılmış açarlar | E10: 4 | F10: 4 | G10: =IF(OR(E10="",F10=""),"",E10*F10) -> 16 | H10: =IF(G10="","",IF(G10>=17,"Kritik",IF(G10>=10,"Yüksək",IF(G10>=5,"Orta","Aşağı")))) -> Yüksək | I10: Azaltmaq | J10: 8.4, 8.28, 5.17 | K10: 5 | N10: =IF(OR(L10="",M10=""),"",L10*M10) | O10: =IF(N10="","",IF(N10>=17,"Kritik",IF(N10>=10,"Yüksək",IF(N10>=5,"Orta","Aşağı"))))
A11: R07 | B11: A05 Kriptoqrafik açarlar | C11: Açarın itirilməsi və ya sui-istifadə | D11: Açar siyasəti və rotasiya yoxdur | E11: 2 | F11: 5 | G11: =IF(OR(E11="",F11=""),"",E11*F11) -> 10 | H11: =IF(G11="","",IF(G11>=17,"Kritik",IF(G11>=10,"Yüksək",IF(G11>=5,"Orta","Aşağı")))) -> Yüksək | I11: Azaltmaq | J11: 8.24, 5.18 | K11: 7 | N11: =IF(OR(L11="",M11=""),"",L11*M11) | O11: =IF(N11="","",IF(N11>=17,"Kritik",IF(N11>=10,"Yüksək",IF(N11>=5,"Orta","Aşağı"))))
A12: R08 | B12: A08 Ehtiyat nüsxələr | C12: Məlumatın bərpa edilməməsi | D12: Ehtiyat nüsxə yoxdur və ya qorunmur | E12: 3 | F12: 4 | G12: =IF(OR(E12="",F12=""),"",E12*F12) -> 12 | H12: =IF(G12="","",IF(G12>=17,"Kritik",IF(G12>=10,"Yüksək",IF(G12>=5,"Orta","Aşağı")))) -> Yüksək | I12: Azaltmaq | J12: 8.13 | K12: 4 | N12: =IF(OR(L12="",M12=""),"",L12*M12) | O12: =IF(N12="","",IF(N12>=17,"Kritik",IF(N12>=10,"Yüksək",IF(N12>=5,"Orta","Aşağı"))))
A13: R09 | B13: A04 IAM identifikasiyaları | C13: İmtiyazların sui-istifadəsi | D13: Həddən artıq geniş icazələr | E13: 3 | F13: 4 | G13: =IF(OR(E13="",F13=""),"",E13*F13) -> 12 | H13: =IF(G13="","",IF(G13>=17,"Kritik",IF(G13>=10,"Yüksək",IF(G13>=5,"Orta","Aşağı")))) -> Yüksək | I13: Azaltmaq | J13: 5.18, 8.2 | K13: 4 | N13: =IF(OR(L13="",M13=""),"",L13*M13) | O13: =IF(N13="","",IF(N13>=17,"Kritik",IF(N13>=10,"Yüksək",IF(N13>=5,"Orta","Aşağı"))))
A14: R10 | B14: A03 Veb server | C14: Zəifliklərin istismarı | D14: Yenilənməmiş proqram təminatı | E14: 3 | F14: 4 | G14: =IF(OR(E14="",F14=""),"",E14*F14) -> 12 | H14: =IF(G14="","",IF(G14>=17,"Kritik",IF(G14>=10,"Yüksək",IF(G14>=5,"Orta","Aşağı")))) -> Yüksək | I14: Azaltmaq | J14: 8.8 | K14: 8 | N14: =IF(OR(L14="",M14=""),"",L14*M14) | O14: =IF(N14="","",IF(N14>=17,"Kritik",IF(N14>=10,"Yüksək",IF(N14>=5,"Orta","Aşağı"))))
A15: R11 | B15: A06 TLS sertifikatları | C15: Açarın oğurlanması və ya müddətin bitməsi | D15: Sertifikat idarəsi yoxdur | E15: 2 | F15: 4 | G15: =IF(OR(E15="",F15=""),"",E15*F15) -> 8 | H15: =IF(G15="","",IF(G15>=17,"Kritik",IF(G15>=10,"Yüksək",IF(G15>=5,"Orta","Aşağı")))) -> Orta | I15: Azaltmaq | J15: 8.24 | K15: 7 | N15: =IF(OR(L15="",M15=""),"",L15*M15) | O15: =IF(N15="","",IF(N15>=17,"Kritik",IF(N15>=10,"Yüksək",IF(N15>=5,"Orta","Aşağı"))))
A16: R12 | B16: A04 AWS hesabı | C16: Açar sızması ilə kriptomaynınq | D16: Billing xəbərdarlığı və monitorinq yoxdur | E16: 3 | F16: 3 | G16: =IF(OR(E16="",F16=""),"",E16*F16) -> 9 | H16: =IF(G16="","",IF(G16>=17,"Kritik",IF(G16>=10,"Yüksək",IF(G16>=5,"Orta","Aşağı")))) -> Orta | I16: Azaltmaq | J16: 8.16 | K16: 0, 5 | N16: =IF(OR(L16="",M16=""),"",L16*M16) | O16: =IF(N16="","",IF(N16>=17,"Kritik",IF(N16>=10,"Yüksək",IF(N16>=5,"Orta","Aşağı"))))
... A19: R15 | B19: A03 Veb server | C19: AWS xidmətinin dayanması | D19: Tək nöqtəli arxitektura | E19: 2 | F19: 3 | G19: =IF(OR(E19="",F19=""),"",E19*F19) -> 6 | H19: =IF(G19="","",IF(G19>=17,"Kritik",IF(G19>=10,"Yüksək",IF(G19>=5,"Orta","Aşağı")))) -> Orta | I19: Qəbul etmək | J19: 5.30 | K19: 9 | N19: =IF(OR(L19="",M19=""),"",L19*M19) | O19: =IF(N19="","",IF(N19>=17,"Kritik",IF(N19>=10,"Yüksək",IF(N19>=5,"Orta","Aşağı"))))
G20: =IF(OR(E20="",F20=""),"",E20*F20) | H20: =IF(G20="","",IF(G20>=17,"Kritik",IF(G20>=10,"Yüksək",IF(G20>=5,"Orta","Aşağı")))) | N20: =IF(OR(L20="",M20=""),"",L20*M20) | O20: =IF(N20="","",IF(N20>=17,"Kritik",IF(N20>=10,"Yüksək",IF(N20>=5,"Orta","Aşağı"))))
G21: =IF(OR(E21="",F21=""),"",E21*F21) | H21: =IF(G21="","",IF(G21>=17,"Kritik",IF(G21>=10,"Yüksək",IF(G21>=5,"Orta","Aşağı")))) | N21: =IF(OR(L21="",M21=""),"",L21*M21) | O21: =IF(N21="","",IF(N21>=17,"Kritik",IF(N21>=10,"Yüksək",IF(N21>=5,"Orta","Aşağı"))))
G22: =IF(OR(E22="",F22=""),"",E22*F22) | H22: =IF(G22="","",IF(G22>=17,"Kritik",IF(G22>=10,"Yüksək",IF(G22>=5,"Orta","Aşağı")))) | N22: =IF(OR(L22="",M22=""),"",L22*M22) | O22: =IF(N22="","",IF(N22>=17,"Kritik",IF(N22>=10,"Yüksək",IF(N22>=5,"Orta","Aşağı"))))
G23: =IF(OR(E23="",F23=""),"",E23*F23) | H23: =IF(G23="","",IF(G23>=17,"Kritik",IF(G23>=10,"Yüksək",IF(G23>=5,"Orta","Aşağı")))) | N23: =IF(OR(L23="",M23=""),"",L23*M23) | O23: =IF(N23="","",IF(N23>=17,"Kritik",IF(N23>=10,"Yüksək",IF(N23>=5,"Orta","Aşağı"))))
G24: =IF(OR(E24="",F24=""),"",E24*F24) | H24: =IF(G24="","",IF(G24>=17,"Kritik",IF(G24>=10,"Yüksək",IF(G24>=5,"Orta","Aşağı")))) | N24: =IF(OR(L24="",M24=""),"",L24*M24) | O24: =IF(N24="","",IF(N24>=17,"Kritik",IF(N24>=10,"Yüksək",IF(N24>=5,"Orta","Aşağı"))))
G25: =IF(OR(E25="",F25=""),"",E25*F25) | H25: =IF(G25="","",IF(G25>=17,"Kritik",IF(G25>=10,"Yüksək",IF(G25>=5,"Orta","Aşağı")))) | N25: =IF(OR(L25="",M25=""),"",L25*M25) | O25: =IF(N25="","",IF(N25>=17,"Kritik",IF(N25>=10,"Yüksək",IF(N25>=5,"Orta","Aşağı"))))
G26: =IF(OR(E26="",F26=""),"",E26*F26) | H26: =IF(G26="","",IF(G26>=17,"Kritik",IF(G26>=10,"Yüksək",IF(G26>=5,"Orta","Aşağı")))) | N26: =IF(OR(L26="",M26=""),"",L26*M26) | O26: =IF(N26="","",IF(N26>=17,"Kritik",IF(N26>=10,"Yüksək",IF(N26>=5,"Orta","Aşağı"))))
G27: =IF(OR(E27="",F27=""),"",E27*F27) | H27: =IF(G27="","",IF(G27>=17,"Kritik",IF(G27>=10,"Yüksək",IF(G27>=5,"Orta","Aşağı")))) | N27: =IF(OR(L27="",M27=""),"",L27*M27) | O27: =IF(N27="","",IF(N27>=17,"Kritik",IF(N27>=10,"Yüksək",IF(N27>=5,"Orta","Aşağı"))))
G28: =IF(OR(E28="",F28=""),"",E28*F28) | H28: =IF(G28="","",IF(G28>=17,"Kritik",IF(G28>=10,"Yüksək",IF(G28>=5,"Orta","Aşağı")))) | N28: =IF(OR(L28="",M28=""),"",L28*M28) | O28: =IF(N28="","",IF(N28>=17,"Kritik",IF(N28>=10,"Yüksək",IF(N28>=5,"Orta","Aşağı"))))
G29: =IF(OR(E29="",F29=""),"",E29*F29) | H29: =IF(G29="","",IF(G29>=17,"Kritik",IF(G29>=10,"Yüksək",IF(G29>=5,"Orta","Aşağı")))) | N29: =IF(OR(L29="",M29=""),"",L29*M29) | O29: =IF(N29="","",IF(N29>=17,"Kritik",IF(N29>=10,"Yüksək",IF(N29>=5,"Orta","Aşağı"))))
G30: =IF(OR(E30="",F30=""),"",E30*F30) | H30: =IF(G30="","",IF(G30>=17,"Kritik",IF(G30>=10,"Yüksək",IF(G30>=5,"Orta","Aşağı")))) | N30: =IF(OR(L30="",M30=""),"",L30*M30) | O30: =IF(N30="","",IF(N30>=17,"Kritik",IF(N30>=10,"Yüksək",IF(N30>=5,"Orta","Aşağı"))))
G31: =IF(OR(E31="",F31=""),"",E31*F31) | H31: =IF(G31="","",IF(G31>=17,"Kritik",IF(G31>=10,"Yüksək",IF(G31>=5,"Orta","Aşağı")))) | N31: =IF(OR(L31="",M31=""),"",L31*M31) | O31: =IF(N31="","",IF(N31>=17,"Kritik",IF(N31>=10,"Yüksək",IF(N31>=5,"Orta","Aşağı"))))
... G34: =IF(OR(E34="",F34=""),"",E34*F34) | H34: =IF(G34="","",IF(G34>=17,"Kritik",IF(G34>=10,"Yüksək",IF(G34>=5,"Orta","Aşağı")))) | N34: =IF(OR(L34="",M34=""),"",L34*M34) | O34: =IF(N34="","",IF(N34>=17,"Kritik",IF(N34>=10,"Yüksək",IF(N34>=5,"Orta","Aşağı"))))

Sheet Risk Matrix
A1: 5×5 risk matrisi: İLKİN (müalicədən əvvəl)
A3: Ehtimal ↓ / Təsir → | B3: 1 Cüzi | C3: 2 Kiçik | D3: 3 Orta | E3: 4 Ciddi | F3: 5 Kritik
A4: 5 Çox yüksək | B4: =_xlfn.TEXTJOIN(", ",TRUE(),IF(AND('Risk Register'!$E$5=5,'Risk Register'!$F$5=1),'Risk Register'!$A$5,""),IF(AND('Risk Register'!$E$6=5,'Risk Register'!$F$6=1),'Risk Register'!$A$6,""),IF(AND('Risk Register'!$E$7=5,'Risk Register'!$F$7=1),'Risk Register'!$A$7,""),IF(AND('Risk Register'!$E$8=5,'Risk Register'!$F$8=1),'Risk Register'!$A$8,""),IF(AND('Risk Register'!$E$9=5,'Risk Register'!$F$9=1),'Risk Register'!$A$9,""),IF(AND('Risk Register'!$E$10=5,'Risk Register'!$F$10=1),'Risk Register'!$A$10,""),IF(AND('Risk Register'!$E$11=5,'Risk Register'!$F$11=1),'Risk Register'!$A$11,""),IF(AND('Risk Register'!$E$12=5,'Risk Register'!$F$12=1),'Risk Register'!$A$12,""),IF(AND('Risk Register'!$E$13=5,'Risk Register'!$F$13=1),'Risk Register'!$A$13,""),IF(AND('Risk Register'!$E$14=5,'Risk Register'!$F$14=1),'Risk Register'!$A$14,""),IF(AND('Risk Register'!$E$15=5,'Risk Register'!$F$15=1),'Risk Register'!$A$15,""),IF(AND('Risk Register'!$E$16=5,'Risk Register'!$F$16=1),'Risk Register'!$A$16,""),IF(AND('Risk Register'!$E$17=5,'Risk Register'!$F$17=1),'Risk Register'!$A$17,""),IF(AND('Risk Register'!$E$18=5,'Risk Register'!$F$18=1),'Risk Register'!$A$18,""),IF(AND('Risk Register'!$E$19=5,'Risk Register'!$F$19=1),'Risk Register'!$A$19,""),IF(AND('Risk Register'!$E$20=5,'Risk Register'!$F$20=1),'Risk Register'!$A$20,""),IF(AND('Risk Register'!$E$21=5,'Risk Register'!$F$21=1),'Risk Register'!$A$21,""),IF(AND('Risk Register'!$E$22=5,'Risk Register'!$F$22=1),'Risk Register'!$A$22,""),IF(AND('Risk Register'!$E$23=5,'Risk Register'!$F$23=1),'Risk Register'!$A$23,""),IF(AND('Risk Register'!$E$24=5,'Risk Register'!$F$24=1),'Risk Register'!$A$24,""),IF(AND('Risk Register'!$E$25=5,'Risk Register'!$F$25=1),'Risk Register'!$A$25,""),IF(AND('Risk Register'!$E$26=5,'Risk Register'!$F$26=1),'Risk Register'!$A$26,""),IF(AND('Risk Register'!$E$27=5,'Risk Register'!$F$27=1),'Risk Register'!$A$27,""),IF(AND('Risk Register'!$E$28=5,'Risk Register'!$F$28=1),'Risk Register'!$A$28,""),IF(AND('Risk Register'!$E$29=5,'Risk Register'!$F$29=1),'Risk Register'!$A$29,""),IF(AND('Risk Register'!$E$30=5,'Risk Register'!$F$30=1),'Risk Register'!$A$30,""),IF(AND('Risk Register'!$E$31=5,'Risk Register'!$F$31=1),'Risk Register'!$A$31,""),IF(AND('Risk Register'!$E$32=5,'Risk Register'!$F$32=1),'Risk Register'!$A$32,""),IF(AND('Risk Register'!$E$33=5,'Risk Register'!$F$33=1),'Risk Register'!$A$33,""),IF(AND('Risk Register'!$E$34=5,'Risk Register'!$F$34=1),'Risk Register'!$A$34,"")) | C4: =_xlfn.TEXTJOIN(", ",TRUE(),IF(AND('Risk Register'!$E$5=5,'Risk Register'!$F$5=2),'Risk Register'!$A$5,""),IF(AND('Risk Register'!$E$6=5,'Risk Register'!$F$6=2),'Risk Register'!$A$6,""),IF(AND('Risk Register'!$E$7=5,'Risk Register'!$F$7=2),'Risk Register'!$A$7,""),IF(AND('Risk Register'!$E$8=5,'Risk Register'!$F$8=2),'Risk Register'!$A$8,""),IF(AND('Risk Register'!$E$9=5,'Risk Register'!$F$9=2),'Risk Register'!$A$9,""),IF(AND('Risk Register'!$E$10=5,'Risk Register'!$F$10=2),'Risk Register'!$A$10,""),IF(AND('Risk Register'!$E$11=5,'Risk Register'!$F$11=2),'Risk Register'!$A$11,""),IF(AND('Risk Register'!$E$12=5,'Risk Register'!$F$12=2),'Risk Register'!$A$12,""),IF(AND('Risk Register'!$E$13=5,'Risk Register'!$F$13=2),'Risk Register'!$A$13,""),IF(AND('Risk Register'!$E$14=5,'Risk Register'!$F$14=2),'Risk Register'!$A$14,""),IF(AND('Risk Register'!$E$15=5,'Risk Register'!$F$15=2),'Risk Register'!$A$15,""),IF(AND('Risk Register'!$E$16=5,'Risk Register'!$F$16=2),'Risk Register'!$A$16,""),IF(AND('Risk Register'!$E$17=5,'Risk Register'!$F$17=2),'Risk Register'!$A$17,""),IF(AND('Risk Register'!$E$18=5,'Risk Register'!$F$18=2),'Risk Register'!$A$18,""),IF(AND('Risk Register'!$E$19=5,'Risk Register'!$F$19=2),'Risk Register'!$A$19,""),IF(AND('Risk Register'!$E$20=5,'Risk Register'!$F$20=2),'Risk Register'!$A$20,""),IF(AND('Risk Register'!$E$21=5,'Risk Register'!$F$21=2),'Risk Register'!$A$21,""),IF(AND('Risk Register'!$E$22=5,'Risk Register'!$F$22=2),'Risk Register'!$A$22,""),IF(AND('Risk Register'!$E$23=5,'Risk Register'!$F$23=2),'Risk Register'!$A$23,""),IF(AND('Risk Register'!$E$24=5,'Risk Register'!$F$24=2),'Risk Register'!$A$24,""),IF(AND('Risk Register'!$E$25=5,'Risk Register'!$F$25=2),'Risk Register'!$A$25,""),IF(AND('Risk Register'!$E$26=5,'Risk Register'!$F$26=2),'Risk Register'!$A$26,""),IF(AND('Risk Register'!$E$27=5,'Risk Register'!$F$27=2),'Risk Register'!$A$27,""),IF(AND('Risk Register'!$E$28=5,'Risk Register'!$F$28=2),'Risk Register'!$A$28,""),IF(AND('Risk Register'!$E$29=5,'Risk Register'!$F$29=2),'Risk Register'!$A$29,""),IF(AND('Risk Register'!$E$30=5,'Risk Register'!$F$30=2),'Risk Register'!$A$30,""),IF(AND('Risk Register'!$E$31=5,'Risk Register'!$F$31=2),'Risk Register'!$A$31,""),IF(AND('Risk Register'!$E$32=5,'Risk Register'!$F$32=2),'Risk Register'!$A$32,""),IF(AND('Risk Register'!$E$33=5,'Risk Register'!$F$33=2),'Risk Register'!$A$33,""),IF(AND('Risk Register'!$E$34=5,'Risk Register'!$F$34=2),'Risk Register'!$A$34,"")) | D4: =_xlfn.TEXTJOIN(", ",TRUE(),IF(AND('Risk Register'!$E$5=5,'Risk Register'!$F$5=3),'Risk Register'!$A$5,""),IF(AND('Risk Register'!$E$6=5,'Risk Register'!$F$6=3),'Risk Register'!$A$6,""),IF(AND('Risk Register'!$E$7=5,'Risk Register'!$F$7=3),'Risk Register'!$A$7,""),IF(AND('Risk Register'!$E$8=5,'Risk Register'!$F$8=3),'Risk Register'!$A$8,""),IF(AND('Risk Register'!$E$9=5,'Risk Register'!$F$9=3),'Risk Register'!$A$9,""),IF(AND('Risk Register'!$E$10=5,'Risk Register'!$F$10=3),'Risk Register'!$A$10,""),IF(AND('Risk Register'!$E$11=5,'Risk Register'!$F$11=3),'Risk Register'!$A$11,""),IF(AND('Risk Register'!$E$12=5,'Risk Register'!$F$12=3),'Risk Register'!$A$12,""),IF(AND('Risk Register'!$E$13=5,'Risk Register'!$F$13=3),'Risk Register'!$A$13,""),IF(AND('Risk Register'!$E$14=5,'Risk Register'!$F$14=3),'Risk Register'!$A$14,""),IF(AND('Risk Register'!$E$15=5,'Risk Register'!$F$15=3),'Risk Register'!$A$15,""),IF(AND('Risk Register'!$E$16=5,'Risk Register'!$F$16=3),'Risk Register'!$A$16,""),IF(AND('Risk Register'!$E$17=5,'Risk Register'!$F$17=3),'Risk Register'!$A$17,""),IF(AND('Risk Register'!$E$18=5,'Risk Register'!$F$18=3),'Risk Register'!$A$18,""),IF(AND('Risk Register'!$E$19=5,'Risk Register'!$F$19=3),'Risk Register'!$A$19,""),IF(AND('Risk Register'!$E$20=5,'Risk Register'!$F$20=3),'Risk Register'!$A$20,""),IF(AND('Risk Register'!$E$21=5,'Risk Register'!$F$21=3),'Risk Register'!$A$21,""),IF(AND('Risk Register'!$E$22=5,'Risk Register'!$F$22=3),'Risk Register'!$A$22,""),IF(AND('Risk Register'!$E$23=5,'Risk Register'!$F$23=3),'Risk Register'!$A$23,""),IF(AND('Risk Register'!$E$24=5,'Risk Register'!$F$24=3),'Risk Register'!$A$24,""),IF(AND('Risk Register'!$E$25=5,'Risk Register'!$F$25=3),'Risk Register'!$A$25,""),IF(AND('Risk Register'!$E$26=5,'Risk Register'!$F$26=3),'Risk Register'!$A$26,""),IF(AND('Risk Register'!$E$27=5,'Risk Register'!$F$27=3),'Risk Register'!$A$27,""),IF(AND('Risk Register'!$E$28=5,'Risk Register'!$F$28=3),'Risk Register'!$A$28,""),IF(AND('Risk Register'!$E$29=5,'Risk Register'!$F$29=3),'Risk Register'!$A$29,""),IF(AND('Risk Register'!$E$30=5,'Risk Register'!$F$30=3),'Risk Register'!$A$30,""),IF(AND('Risk Register'!$E$31=5,'Risk Register'!$F$31=3),'Risk Register'!$A$31,""),IF(AND('Risk Register'!$E$32=5,'Risk Register'!$F$32=3),'Risk Register'!$A$32,""),IF(AND('Risk Register'!$E$33=5,'Risk Register'!$F$33=3),'Risk Register'!$A$33,""),IF(AND('Risk Register'!$E$34=5,'Risk Register'!$F$34=3),'Risk Register'!$A$34,"")) | E4: =_xlfn.TEXTJOIN(", ",TRUE(),IF(AND('Risk Register'!$E$5=5,'Risk Register'!$F$5=4),'Risk Register'!$A$5,""),IF(AND('Risk Register'!$E$6=5,'Risk Register'!$F$6=4),'Risk Register'!$A$6,""),IF(AND('Risk Register'!$E$7=5,'Risk Register'!$F$7=4),'Risk Register'!$A$7,""),IF(AND('Risk Register'!$E$8=5,'Risk Register'!$F$8=4),'Risk Register'!$A$8,""),IF(AND('Risk Register'!$E$9=5,'Risk Register'!$F$9=4),'Risk Register'!$A$9,""),IF(AND('Risk Register'!$E$10=5,'Risk Register'!$F$10=4),'Risk Register'!$A$10,""),IF(AND('Risk Register'!$E$11=5,'Risk Register'!$F$11=4),'Risk Register'!$A$11,""),IF(AND('Risk Register'!$E$12=5,'Risk Register'!$F$12=4),'Risk Register'!$A$12,""),IF(AND('Risk Register'!$E$13=5,'Risk Register'!$F$13=4),'Risk Register'!$A$13,""),IF(AND('Risk Register'!$E$14=5,'Risk Register'!$F$14=4),'Risk Register'!$A$14,""),IF(AND('Risk Register'!$E$15=5,'Risk Register'!$F$15=4),'Risk Register'!$A$15,""),IF(AND('Risk Register'!$E$16=5,'Risk Register'!$F$16=4),'Risk Register'!$A$16,""),IF(AND('Risk Register'!$E$17=5,'Risk Register'!$F$17=4),'Risk Register'!$A$17,""),IF(AND('Risk Register'!$E$18=5,'Risk Register'!$F$18=4),'Risk Register'!$A$18,""),IF(AND('Risk Register'!$E$19=5,'Risk Register'!$F$19=4),'Risk Register'!$A$19,""),IF(AND('Risk Register'!$E$20=5,'Risk Register'!$F$20=4),'Risk Register'!$A$20,""),IF(AND('Risk Register'!$E$21=5,'Risk Register'!$F$21=4),'Risk Register'!$A$21,""),IF(AND('Risk Register'!$E$22=5,'Risk Register'!$F$22=4),'Risk Register'!$A$22,""),IF(AND('Risk Register'!$E$23=5,'Risk Register'!$F$23=4),'Risk Register'!$A$23,""),IF(AND('Risk Register'!$E$24=5,'Risk Register'!$F$24=4),'Risk Register'!$A$24,""),IF(AND('Risk Register'!$E$25=5,'Risk Register'!$F$25=4),'Risk Register'!$A$25,""),IF(AND('Risk Register'!$E$26=5,'Risk Register'!$F$26=4),'Risk Register'!$A$26,""),IF(AND('Risk Register'!$E$27=5,'Risk Register'!$F$27=4),'Risk Register'!$A$27,""),IF(AND('Risk Register'!$E$28=5,'Risk Register'!$F$28=4),'Risk Register'!$A$28,""),IF(AND('Risk Register'!$E$29=5,'Risk Register'!$F$29=4),'Risk Register'!$A$29,""),IF(AND('Risk Register'!$E$30=5,'Risk Register'!$F$30=4),'Risk Register'!$A$30,""),IF(AND('Risk Register'!$E$31=5,'Risk Register'!$F$31=4),'Risk Register'!$A$31,""),IF(AND('Risk Register'!$E$32=5,'Risk Register'!$F$32=4),'Risk Register'!$A$32,""),IF(AND('Risk Register'!$E$33=5,'Risk Register'!$F$33=4),'Risk Register'!$A$33,""),IF(AND('Risk Register'!$E$34=5,'Risk Register'!$F$34=4),'Risk Register'!$A$34,"")) | F4: =_xlfn.TEXTJOIN(", ",TRUE(),IF(AND('Risk Register'!$E$5=5,'Risk Register'!$F$5=5),'Risk Register'!$A$5,""),IF(AND('Risk Register'!$E$6=5,'Risk Register'!$F$6=5),'Risk Register'!$A$6,""),IF(AND('Risk Register'!$E$7=5,'Risk Register'!$F$7=5),'Risk Register'!$A$7,""),IF(AND('Risk Register'!$E$8=5,'Risk Register'!$F$8=5),'Risk Register'!$A$8,""),IF(AND('Risk Register'!$E$9=5,'Risk Register'!$F$9=5),'Risk Register'!$A$9,""),IF(AND('Risk Register'!$E$10=5,'Risk Register'!$F$10=5),'Risk Register'!$A$10,""),IF(AND('Risk Register'!$E$11=5,'Risk Register'!$F$11=5),'Risk Register'!$A$11,""),IF(AND('Risk Register'!$E$12=5,'Risk Register'!$F$12=5),'Risk Register'!$A$12,""),IF(AND('Risk Register'!$E$13=5,'Risk Register'!$F$13=5),'Risk Register'!$A$13,""),IF(AND('Risk Register'!$E$14=5,'Risk Register'!$F$14=5),'Risk Register'!$A$14,""),IF(AND('Risk Register'!$E$15=5,'Risk Register'!$F$15=5),'Risk Register'!$A$15,""),IF(AND('Risk Register'!$E$16=5,'Risk Register'!$F$16=5),'Risk Register'!$A$16,""),IF(AND('Risk Register'!$E$17=5,'Risk Register'!$F$17=5),'Risk Register'!$A$17,""),IF(AND('Risk Register'!$E$18=5,'Risk Register'!$F$18=5),'Risk Register'!$A$18,""),IF(AND('Risk Register'!$E$19=5,'Risk Register'!$F$19=5),'Risk Register'!$A$19,""),IF(AND('Risk Register'!$E$20=5,'Risk Register'!$F$20=5),'Risk Register'!$A$20,""),IF(AND('Risk Register'!$E$21=5,'Risk Register'!$F$21=5),'Risk Register'!$A$21,""),IF(AND('Risk Register'!$E$22=5,'Risk Register'!$F$22=5),'Risk Register'!$A$22,""),IF(AND('Risk Register'!$E$23=5,'Risk Register'!$F$23=5),'Risk Register'!$A$23,""),IF(AND('Risk Register'!$E$24=5,'Risk Register'!$F$24=5),'Risk Register'!$A$24,""),IF(AND('Risk Register'!$E$25=5,'Risk Register'!$F$25=5),'Risk Register'!$A$25,""),IF(AND('Risk Register'!$E$26=5,'Risk Register'!$F$26=5),'Risk Register'!$A$26,""),IF(AND('Risk Register'!$E$27=5,'Risk Register'!$F$27=5),'Risk Register'!$A$27,""),IF(AND('Risk Register'!$E$28=5,'Risk Register'!$F$28=5),'Risk Register'!$A$28,""),IF(AND('Risk Register'!$E$29=5,'Risk Register'!$F$29=5),'Risk Register'!$A$29,""),IF(AND('Risk Register'!$E$30=5,'Risk Register'!$F$30=5),'Risk Register'!$A$30,""),IF(AND('Risk Register'!$E$31=5,'Risk Register'!$F$31=5),'Risk Register'!$A$31,""),IF(AND('Risk Register'!$E$32=5,'Risk Register'!$F$32=5),'Risk Register'!$A$32,""),IF(AND('Risk Register'!$E$33=5,'Risk Register'!$F$33=5),'Risk Register'!$A$33,""),IF(AND('Risk Register'!$E$34=5,'Risk Register'!$F$34=5),'Risk Register'!$A$34,""))
A5: 4 Yüksək | B5: =_xlfn.TEXTJOIN(", ",TRUE(),IF(AND('Risk Register'!$E$5=4,'Risk Register'!$F$5=1),'Risk Register'!$A$5,""),IF(AND('Risk Register'!$E$6=4,'Risk Register'!$F$6=1),'Risk Register'!$A$6,""),IF(AND('Risk Register'!$E$7=4,'Risk Register'!$F$7=1),'Risk Register'!$A$7,""),IF(AND('Risk Register'!$E$8=4,'Risk Register'!$F$8=1),'Risk Register'!$A$8,""),IF(AND('Risk Register'!$E$9=4,'Risk Register'!$F$9=1),'Risk Register'!$A$9,""),IF(AND('Risk Register'!$E$10=4,'Risk Register'!$F$10=1),'Risk Register'!$A$10,""),IF(AND('Risk Register'!$E$11=4,'Risk Register'!$F$11=1),'Risk Register'!$A$11,""),IF(AND('Risk Register'!$E$12=4,'Risk Register'!$F$12=1),'Risk Register'!$A$12,""),IF(AND('Risk Register'!$E$13=4,'Risk Register'!$F$13=1),'Risk Register'!$A$13,""),IF(AND('Risk Register'!$E$14=4,'Risk Register'!$F$14=1),'Risk Register'!$A$14,""),IF(AND('Risk Register'!$E$15=4,'Risk Register'!$F$15=1),'Risk Register'!$A$15,""),IF(AND('Risk Register'!$E$16=4,'Risk Register'!$F$16=1),'Risk Register'!$A$16,""),IF(AND('Risk Register'!$E$17=4,'Risk Register'!$F$17=1),'Risk Register'!$A$17,""),IF(AND('Risk Register'!$E$18=4,'Risk Register'!$F$18=1),'Risk Register'!$A$18,""),IF(AND('Risk Register'!$E$19=4,'Risk Register'!$F$19=1),'Risk Register'!$A$19,""),IF(AND('Risk Register'!$E$20=4,'Risk Register'!$F$20=1),'Risk Register'!$A$20,""),IF(AND('Risk Register'!$E$21=4,'Risk Register'!$F$21=1),'Risk Register'!$A$21,""),IF(AND('Risk Register'!$E$22=4,'Risk Register'!$F$22=1),'Risk Register'!$A$22,""),IF(AND('Risk Register'!$E$23=4,'Risk Register'!$F$23=1),'Risk Register'!$A$23,""),IF(AND('Risk Register'!$E$24=4,'Risk Register'!$F$24=1),'Risk Register'!$A$24,""),IF(AND('Risk Register'!$E$25=4,'Risk Register'!$F$25=1),'Risk Register'!$A$25,""),IF(AND('Risk Register'!$E$26=4,'Risk Register'!$F$26=1),'Risk Register'!$A$26,""),IF(AND('Risk Register'!$E$27=4,'Risk Register'!$F$27=1),'Risk Register'!$A$27,""),IF(AND('Risk Register'!$E$28=4,'Risk Register'!$F$28=1),'Risk Register'!$A$28,""),IF(AND('Risk Register'!$E$29=4,'Risk Register'!$F$29=1),'Risk Register'!$A$29,""),IF(AND('Risk Register'!$E$30=4,'Risk Register'!$F$30=1),'Risk Register'!$A$30,""),IF(AND('Risk Register'!$E$31=4,'Risk Register'!$F$31=1),'Risk Register'!$A$31,""),IF(AND('Risk Register'!$E$32=4,'Risk Register'!$F$32=1),'Risk Register'!$A$32,""),IF(AND('Risk Register'!$E$33=4,'Risk Register'!$F$33=1),'Risk Register'!$A$33,""),IF(AND('Risk Register'!$E$34=4,'Risk Register'!$F$34=1),'Risk Register'!$A$34,"")) | C5: =_xlfn.TEXTJOIN(", ",TRUE(),IF(AND('Risk Register'!$E$5=4,'Risk Register'!$F$5=2),'Risk Register'!$A$5,""),IF(AND('Risk Register'!$E$6=4,'Risk Register'!$F$6=2),'Risk Register'!$A$6,""),IF(AND('Risk Register'!$E$7=4,'Risk Register'!$F$7=2),'Risk Register'!$A$7,""),IF(AND('Risk Register'!$E$8=4,'Risk Register'!$F$8=2),'Risk Register'!$A$8,""),IF(AND('Risk Register'!$E$9=4,'Risk Register'!$F$9=2),'Risk Register'!$A$9,""),IF(AND('Risk Register'!$E$10=4,'Risk Register'!$F$10=2),'Risk Register'!$A$10,""),IF(AND('Risk Register'!$E$11=4,'Risk Register'!$F$11=2),'Risk Register'!$A$11,""),IF(AND('Risk Register'!$E$12=4,'Risk Register'!$F$12=2),'Risk Register'!$A$12,""),IF(AND('Risk Register'!$E$13=4,'Risk Register'!$F$13=2),'Risk Register'!$A$13,""),IF(AND('Risk Register'!$E$14=4,'Risk Register'!$F$14=2),'Risk Register'!$A$14,""),IF(AND('Risk Register'!$E$15=4,'Risk Register'!$F$15=2),'Risk Register'!$A$15,""),IF(AND('Risk Register'!$E$16=4,'Risk Register'!$F$16=2),'Risk Register'!$A$16,""),IF(AND('Risk Register'!$E$17=4,'Risk Register'!$F$17=2),'Risk Register'!$A$17,""),IF(AND('Risk Register'!$E$18=4,'Risk Register'!$F$18=2),'Risk Register'!$A$18,""),IF(AND('Risk Register'!$E$19=4,'Risk Register'!$F$19=2),'Risk Register'!$A$19,""),IF(AND('Risk Register'!$E$20=4,'Risk Register'!$F$20=2),'Risk Register'!$A$20,""),IF(AND('Risk Register'!$E$21=4,'Risk Register'!$F$21=2),'Risk Register'!$A$21,""),IF(AND('Risk Register'!$E$22=4,'Risk Register'!$F$22=2),'Risk Register'!$A$22,""),IF(AND('Risk Register'!$E$23=4,'Risk Register'!$F$23=2),'Risk Register'!$A$23,""),IF(AND('Risk Register'!$E$24=4,'Risk Register'!$F$24=2),'Risk Register'!$A$24,""),IF(AND('Risk Register'!$E$25=4,'Risk Register'!$F$25=2),'Risk Register'!$A$25,""),IF(AND('Risk Register'!$E$26=4,'Risk Register'!$F$26=2),'Risk Register'!$A$26,""),IF(AND('Risk Register'!$E$27=4,'Risk Register'!$F$27=2),'Risk Register'!$A$27,""),IF(AND('Risk Register'!$E$28=4,'Risk Register'!$F$28=2),'Risk Register'!$A$28,""),IF(AND('Risk Register'!$E$29=4,'Risk Register'!$F$29=2),'Risk Register'!$A$29,""),IF(AND('Risk Register'!$E$30=4,'Risk Register'!$F$30=2),'Risk Register'!$A$30,""),IF(AND('Risk Register'!$E$31=4,'Risk Register'!$F$31=2),'Risk Register'!$A$31,""),IF(AND('Risk Register'!$E$32=4,'Risk Register'!$F$32=2),'Risk Register'!$A$32,""),IF(AND('Risk Register'!$E$33=4,'Risk Register'!$F$33=2),'Risk Register'!$A$33,""),IF(AND('Risk Register'!$E$34=4,'Risk Register'!$F$34=2),'Risk Register'!$A$34,"")) | D5: =_xlfn.TEXTJOIN(", ",TRUE(),IF(AND('Risk Register'!$E$5=4,'Risk Register'!$F$5=3),'Risk Register'!$A$5,""),IF(AND('Risk Register'!$E$6=4,'Risk Register'!$F$6=3),'Risk Register'!$A$6,""),IF(AND('Risk Register'!$E$7=4,'Risk Register'!$F$7=3),'Risk Register'!$A$7,""),IF(AND('Risk Register'!$E$8=4,'Risk Register'!$F$8=3),'Risk Register'!$A$8,""),IF(AND('Risk Register'!$E$9=4,'Risk Register'!$F$9=3),'Risk Register'!$A$9,""),IF(AND('Risk Register'!$E$10=4,'Risk Register'!$F$10=3),'Risk Register'!$A$10,""),IF(AND('Risk Register'!$E$11=4,'Risk Register'!$F$11=3),'Risk Register'!$A$11,""),IF(AND('Risk Register'!$E$12=4,'Risk Register'!$F$12=3),'Risk Register'!$A$12,""),IF(AND('Risk Register'!$E$13=4,'Risk Register'!$F$13=3),'Risk Register'!$A$13,""),IF(AND('Risk Register'!$E$14=4,'Risk Register'!$F$14=3),'Risk Register'!$A$14,""),IF(AND('Risk Register'!$E$15=4,'Risk Register'!$F$15=3),'Risk Register'!$A$15,""),IF(AND('Risk Register'!$E$16=4,'Risk Register'!$F$16=3),'Risk Register'!$A$16,""),IF(AND('Risk Register'!$E$17=4,'Risk Register'!$F$17=3),'Risk Register'!$A$17,""),IF(AND('Risk Register'!$E$18=4,'Risk Register'!$F$18=3),'Risk Register'!$A$18,""),IF(AND('Risk Register'!$E$19=4,'Risk Register'!$F$19=3),'Risk Register'!$A$19,""),IF(AND('Risk Register'!$E$20=4,'Risk Register'!$F$20=3),'Risk Register'!$A$20,""),IF(AND('Risk Register'!$E$21=4,'Risk Register'!$F$21=3),'Risk Register'!$A$21,""),IF(AND('Risk Register'!$E$22=4,'Risk Register'!$F$22=3),'Risk Register'!$A$22,""),IF(AND('Risk Register'!$E$23=4,'Risk Register'!$F$23=3),'Risk Register'!$A$23,""),IF(AND('Risk Register'!$E$24=4,'Risk Register'!$F$24=3),'Risk Register'!$A$24,""),IF(AND('Risk Register'!$E$25=4,'Risk Register'!$F$25=3),'Risk Register'!$A$25,""),IF(AND('Risk Register'!$E$26=4,'Risk Register'!$F$26=3),'Risk Register'!$A$26,""),IF(AND('Risk Register'!$E$27=4,'Risk Register'!$F$27=3),'Risk Register'!$A$27,""),IF(AND('Risk Register'!$E$28=4,'Risk Register'!$F$28=3),'Risk Register'!$A$28,""),IF(AND('Risk Register'!$E$29=4,'Risk Register'!$F$29=3),'Risk Register'!$A$29,""),IF(AND('Risk Register'!$E$30=4,'Risk Register'!$F$30=3),'Risk Register'!$A$30,""),IF(AND('Risk Register'!$E$31=4,'Risk Register'!$F$31=3),'Risk Register'!$A$31,""),IF(AND('Risk Register'!$E$32=4,'Risk Register'!$F$32=3),'Risk Register'!$A$32,""),IF(AND('Risk Register'!$E$33=4,'Risk Register'!$F$33=3),'Risk Register'!$A$33,""),IF(AND('Risk Register'!$E$34=4,'Risk Register'!$F$34=3),'Risk Register'!$A$34,"")) | E5: =_xlfn.TEXTJOIN(", ",TRUE(),IF(AND('Risk Register'!$E$5=4,'Risk Register'!$F$5=4),'Risk Register'!$A$5,""),IF(AND('Risk Register'!$E$6=4,'Risk Register'!$F$6=4),'Risk Register'!$A$6,""),IF(AND('Risk Register'!$E$7=4,'Risk Register'!$F$7=4),'Risk Register'!$A$7,""),IF(AND('Risk Register'!$E$8=4,'Risk Register'!$F$8=4),'Risk Register'!$A$8,""),IF(AND('Risk Register'!$E$9=4,'Risk Register'!$F$9=4),'Risk Register'!$A$9,""),IF(AND('Risk Register'!$E$10=4,'Risk Register'!$F$10=4),'Risk Register'!$A$10,""),IF(AND('Risk Register'!$E$11=4,'Risk Register'!$F$11=4),'Risk Register'!$A$11,""),IF(AND('Risk Register'!$E$12=4,'Risk Register'!$F$12=4),'Risk Register'!$A$12,""),IF(AND('Risk Register'!$E$13=4,'Risk Register'!$F$13=4),'Risk Register'!$A$13,""),IF(AND('Risk Register'!$E$14=4,'Risk Register'!$F$14=4),'Risk Register'!$A$14,""),IF(AND('Risk Register'!$E$15=4,'Risk Register'!$F$15=4),'Risk Register'!$A$15,""),IF(AND('Risk Register'!$E$16=4,'Risk Register'!$F$16=4),'Risk Register'!$A$16,""),IF(AND('Risk Register'!$E$17=4,'Risk Register'!$F$17=4),'Risk Register'!$A$17,""),IF(AND('Risk Register'!$E$18=4,'Risk Register'!$F$18=4),'Risk Register'!$A$18,""),IF(AND('Risk Register'!$E$19=4,'Risk Register'!$F$19=4),'Risk Register'!$A$19,""),IF(AND('Risk Register'!$E$20=4,'Risk Register'!$F$20=4),'Risk Register'!$A$20,""),IF(AND('Risk Register'!$E$21=4,'Risk Register'!$F$21=4),'Risk Register'!$A$21,""),IF(AND('Risk Register'!$E$22=4,'Risk Register'!$F$22=4),'Risk Register'!$A$22,""),IF(AND('Risk Register'!$E$23=4,'Risk Register'!$F$23=4),'Risk Register'!$A$23,""),IF(AND('Risk Register'!$E$24=4,'Risk Register'!$F$24=4),'Risk Register'!$A$24,""),IF(AND('Risk Register'!$E$25=4,'Risk Register'!$F$25=4),'Risk Register'!$A$25,""),IF(AND('Risk Register'!$E$26=4,'Risk Register'!$F$26=4),'Risk Register'!$A$26,""),IF(AND('Risk Register'!$E$27=4,'Risk Register'!$F$27=4),'Risk Register'!$A$27,""),IF(AND('Risk Register'!$E$28=4,'Risk Register'!$F$28=4),'Risk Register'!$A$28,""),IF(AND('Risk Register'!$E$29=4,'Risk Register'!$F$29=4),'Risk Register'!$A$29,""),IF(AND('Risk Register'!$E$30=4,'Risk Register'!$F$30=4),'Risk Register'!$A$30,""),IF(AND('Risk Register'!$E$31=4,'Risk Register'!$F$31=4),'Risk Register'!$A$31,""),IF(AND('Risk Register'!$E$32=4,'Risk Register'!$F$32=4),'Risk Register'!$A$32,""),IF(AND('Risk Register'!$E$33=4,'Risk Register'!$F$33=4),'Risk Register'!$A$33,""),IF(AND('Risk Register'!$E$34=4,'Risk Register'!$F$34=4),'Risk Register'!$A$34,"")) -> R04, R05, R06 | F5: =_xlfn.TEXTJOIN(", ",TRUE(),IF(AND('Risk Register'!$E$5=4,'Risk Register'!$F$5=5),'Risk Register'!$A$5,""),IF(AND('Risk Register'!$E$6=4,'Risk Register'!$F$6=5),'Risk Register'!$A$6,""),IF(AND('Risk Register'!$E$7=4,'Risk Register'!$F$7=5),'Risk Register'!$A$7,""),IF(AND('Risk Register'!$E$8=4,'Risk Register'!$F$8=5),'Risk Register'!$A$8,""),IF(AND('Risk Register'!$E$9=4,'Risk Register'!$F$9=5),'Risk Register'!$A$9,""),IF(AND('Risk Register'!$E$10=4,'Risk Register'!$F$10=5),'Risk Register'!$A$10,""),IF(AND('Risk Register'!$E$11=4,'Risk Register'!$F$11=5),'Risk Register'!$A$11,""),IF(AND('Risk Register'!$E$12=4,'Risk Register'!$F$12=5),'Risk Register'!$A$12,""),IF(AND('Risk Register'!$E$13=4,'Risk Register'!$F$13=5),'Risk Register'!$A$13,""),IF(AND('Risk Register'!$E$14=4,'Risk Register'!$F$14=5),'Risk Register'!$A$14,""),IF(AND('Risk Register'!$E$15=4,'Risk Register'!$F$15=5),'Risk Register'!$A$15,""),IF(AND('Risk Register'!$E$16=4,'Risk Register'!$F$16=5),'Risk Register'!$A$16,""),IF(AND('Risk Register'!$E$17=4,'Risk Register'!$F$17=5),'Risk Register'!$A$17,""),IF(AND('Risk Register'!$E$18=4,'Risk Register'!$F$18=5),'Risk Register'!$A$18,""),IF(AND('Risk Register'!$E$19=4,'Risk Register'!$F$19=5),'Risk Register'!$A$19,""),IF(AND('Risk Register'!$E$20=4,'Risk Register'!$F$20=5),'Risk Register'!$A$20,""),IF(AND('Risk Register'!$E$21=4,'Risk Register'!$F$21=5),'Risk Register'!$A$21,""),IF(AND('Risk Register'!$E$22=4,'Risk Register'!$F$22=5),'Risk Register'!$A$22,""),IF(AND('Risk Register'!$E$23=4,'Risk Register'!$F$23=5),'Risk Register'!$A$23,""),IF(AND('Risk Register'!$E$24=4,'Risk Register'!$F$24=5),'Risk Register'!$A$24,""),IF(AND('Risk Register'!$E$25=4,'Risk Register'!$F$25=5),'Risk Register'!$A$25,""),IF(AND('Risk Register'!$E$26=4,'Risk Register'!$F$26=5),'Risk Register'!$A$26,""),IF(AND('Risk Register'!$E$27=4,'Risk Register'!$F$27=5),'Risk Register'!$A$27,""),IF(AND('Risk Register'!$E$28=4,'Risk Register'!$F$28=5),'Risk Register'!$A$28,""),IF(AND('Risk Register'!$E$29=4,'Risk Register'!$F$29=5),'Risk Register'!$A$29,""),IF(AND('Risk Register'!$E$30=4,'Risk Register'!$F$30=5),'Risk Register'!$A$30,""),IF(AND('Risk Register'!$E$31=4,'Risk Register'!$F$31=5),'Risk Register'!$A$31,""),IF(AND('Risk Register'!$E$32=4,'Risk Register'!$F$32=5),'Risk Register'!$A$32,""),IF(AND('Risk Register'!$E$33=4,'Risk Register'!$F$33=5),'Risk Register'!$A$33,""),IF(AND('Risk Register'!$E$34=4,'Risk Register'!$F$34=5),'Risk Register'!$A$34,"")) -> R01
A6: 3 Orta | B6: =_xlfn.TEXTJOIN(", ",TRUE(),IF(AND('Risk Register'!$E$5=3,'Risk Register'!$F$5=1),'Risk Register'!$A$5,""),IF(AND('Risk Register'!$E$6=3,'Risk Register'!$F$6=1),'Risk Register'!$A$6,""),IF(AND('Risk Register'!$E$7=3,'Risk Register'!$F$7=1),'Risk Register'!$A$7,""),IF(AND('Risk Register'!$E$8=3,'Risk Register'!$F$8=1),'Risk Register'!$A$8,""),IF(AND('Risk Register'!$E$9=3,'Risk Register'!$F$9=1),'Risk Register'!$A$9,""),IF(AND('Risk Register'!$E$10=3,'Risk Register'!$F$10=1),'Risk Register'!$A$10,""),IF(AND('Risk Register'!$E$11=3,'Risk Register'!$F$11=1),'Risk Register'!$A$11,""),IF(AND('Risk Register'!$E$12=3,'Risk Register'!$F$12=1),'Risk Register'!$A$12,""),IF(AND('Risk Register'!$E$13=3,'Risk Register'!$F$13=1),'Risk Register'!$A$13,""),IF(AND('Risk Register'!$E$14=3,'Risk Register'!$F$14=1),'Risk Register'!$A$14,""),IF(AND('Risk Register'!$E$15=3,'Risk Register'!$F$15=1),'Risk Register'!$A$15,""),IF(AND('Risk Register'!$E$16=3,'Risk Register'!$F$16=1),'Risk Register'!$A$16,""),IF(AND('Risk Register'!$E$17=3,'Risk Register'!$F$17=1),'Risk Register'!$A$17,""),IF(AND('Risk Register'!$E$18=3,'Risk Register'!$F$18=1),'Risk Register'!$A$18,""),IF(AND('Risk Register'!$E$19=3,'Risk Register'!$F$19=1),'Risk Register'!$A$19,""),IF(AND('Risk Register'!$E$20=3,'Risk Register'!$F$20=1),'Risk Register'!$A$20,""),IF(AND('Risk Register'!$E$21=3,'Risk Register'!$F$21=1),'Risk Register'!$A$21,""),IF(AND('Risk Register'!$E$22=3,'Risk Register'!$F$22=1),'Risk Register'!$A$22,""),IF(AND('Risk Register'!$E$23=3,'Risk Register'!$F$23=1),'Risk Register'!$A$23,""),IF(AND('Risk Register'!$E$24=3,'Risk Register'!$F$24=1),'Risk Register'!$A$24,""),IF(AND('Risk Register'!$E$25=3,'Risk Register'!$F$25=1),'Risk Register'!$A$25,""),IF(AND('Risk Register'!$E$26=3,'Risk Register'!$F$26=1),'Risk Register'!$A$26,""),IF(AND('Risk Register'!$E$27=3,'Risk Register'!$F$27=1),'Risk Register'!$A$27,""),IF(AND('Risk Register'!$E$28=3,'Risk Register'!$F$28=1),'Risk Register'!$A$28,""),IF(AND('Risk Register'!$E$29=3,'Risk Register'!$F$29=1),'Risk Register'!$A$29,""),IF(AND('Risk Register'!$E$30=3,'Risk Register'!$F$30=1),'Risk Register'!$A$30,""),IF(AND('Risk Register'!$E$31=3,'Risk Register'!$F$31=1),'Risk Register'!$A$31,""),IF(AND('Risk Register'!$E$32=3,'Risk Register'!$F$32=1),'Risk Register'!$A$32,""),IF(AND('Risk Register'!$E$33=3,'Risk Register'!$F$33=1),'Risk Register'!$A$33,""),IF(AND('Risk Register'!$E$34=3,'Risk Register'!$F$34=1),'Risk Register'!$A$34,"")) | C6: =_xlfn.TEXTJOIN(", ",TRUE(),IF(AND('Risk Register'!$E$5=3,'Risk Register'!$F$5=2),'Risk Register'!$A$5,""),IF(AND('Risk Register'!$E$6=3,'Risk Register'!$F$6=2),'Risk Register'!$A$6,""),IF(AND('Risk Register'!$E$7=3,'Risk Register'!$F$7=2),'Risk Register'!$A$7,""),IF(AND('Risk Register'!$E$8=3,'Risk Register'!$F$8=2),'Risk Register'!$A$8,""),IF(AND('Risk Register'!$E$9=3,'Risk Register'!$F$9=2),'Risk Register'!$A$9,""),IF(AND('Risk Register'!$E$10=3,'Risk Register'!$F$10=2),'Risk Register'!$A$10,""),IF(AND('Risk Register'!$E$11=3,'Risk Register'!$F$11=2),'Risk Register'!$A$11,""),IF(AND('Risk Register'!$E$12=3,'Risk Register'!$F$12=2),'Risk Register'!$A$12,""),IF(AND('Risk Register'!$E$13=3,'Risk Register'!$F$13=2),'Risk Register'!$A$13,""),IF(AND('Risk Register'!$E$14=3,'Risk Register'!$F$14=2),'Risk Register'!$A$14,""),IF(AND('Risk Register'!$E$15=3,'Risk Register'!$F$15=2),'Risk Register'!$A$15,""),IF(AND('Risk Register'!$E$16=3,'Risk Register'!$F$16=2),'Risk Register'!$A$16,""),IF(AND('Risk Register'!$E$17=3,'Risk Register'!$F$17=2),'Risk Register'!$A$17,""),IF(AND('Risk Register'!$E$18=3,'Risk Register'!$F$18=2),'Risk Register'!$A$18,""),IF(AND('Risk Register'!$E$19=3,'Risk Register'!$F$19=2),'Risk Register'!$A$19,""),IF(AND('Risk Register'!$E$20=3,'Risk Register'!$F$20=2),'Risk Register'!$A$20,""),IF(AND('Risk Register'!$E$21=3,'Risk Register'!$F$21=2),'Risk Register'!$A$21,""),IF(AND('Risk Register'!$E$22=3,'Risk Register'!$F$22=2),'Risk Register'!$A$22,""),IF(AND('Risk Register'!$E$23=3,'Risk Register'!$F$23=2),'Risk Register'!$A$23,""),IF(AND('Risk Register'!$E$24=3,'Risk Register'!$F$24=2),'Risk Register'!$A$24,""),IF(AND('Risk Register'!$E$25=3,'Risk Register'!$F$25=2),'Risk Register'!$A$25,""),IF(AND('Risk Register'!$E$26=3,'Risk Register'!$F$26=2),'Risk Register'!$A$26,""),IF(AND('Risk Register'!$E$27=3,'Risk Register'!$F$27=2),'Risk Register'!$A$27,""),IF(AND('Risk Register'!$E$28=3,'Risk Register'!$F$28=2),'Risk Register'!$A$28,""),IF(AND('Risk Register'!$E$29=3,'Risk Register'!$F$29=2),'Risk Register'!$A$29,""),IF(AND('Risk Register'!$E$30=3,'Risk Register'!$F$30=2),'Risk Register'!$A$30,""),IF(AND('Risk Register'!$E$31=3,'Risk Register'!$F$31=2),'Risk Register'!$A$31,""),IF(AND('Risk Register'!$E$32=3,'Risk Register'!$F$32=2),'Risk Register'!$A$32,""),IF(AND('Risk Register'!$E$33=3,'Risk Register'!$F$33=2),'Risk Register'!$A$33,""),IF(AND('Risk Register'!$E$34=3,'Risk Register'!$F$34=2),'Risk Register'!$A$34,"")) | D6: =_xlfn.TEXTJOIN(", ",TRUE(),IF(AND('Risk Register'!$E$5=3,'Risk Register'!$F$5=3),'Risk Register'!$A$5,""),IF(AND('Risk Register'!$E$6=3,'Risk Register'!$F$6=3),'Risk Register'!$A$6,""),IF(AND('Risk Register'!$E$7=3,'Risk Register'!$F$7=3),'Risk Register'!$A$7,""),IF(AND('Risk Register'!$E$8=3,'Risk Register'!$F$8=3),'Risk Register'!$A$8,""),IF(AND('Risk Register'!$E$9=3,'Risk Register'!$F$9=3),'Risk Register'!$A$9,""),IF(AND('Risk Register'!$E$10=3,'Risk Register'!$F$10=3),'Risk Register'!$A$10,""),IF(AND('Risk Register'!$E$11=3,'Risk Register'!$F$11=3),'Risk Register'!$A$11,""),IF(AND('Risk Register'!$E$12=3,'Risk Register'!$F$12=3),'Risk Register'!$A$12,""),IF(AND('Risk Register'!$E$13=3,'Risk Register'!$F$13=3),'Risk Register'!$A$13,""),IF(AND('Risk Register'!$E$14=3,'Risk Register'!$F$14=3),'Risk Register'!$A$14,""),IF(AND('Risk Register'!$E$15=3,'Risk Register'!$F$15=3),'Risk Register'!$A$15,""),IF(AND('Risk Register'!$E$16=3,'Risk Register'!$F$16=3),'Risk Register'!$A$16,""),IF(AND('Risk Register'!$E$17=3,'Risk Register'!$F$17=3),'Risk Register'!$A$17,""),IF(AND('Risk Register'!$E$18=3,'Risk Register'!$F$18=3),'Risk Register'!$A$18,""),IF(AND('Risk Register'!$E$19=3,'Risk Register'!$F$19=3),'Risk Register'!$A$19,""),IF(AND('Risk Register'!$E$20=3,'Risk Register'!$F$20=3),'Risk Register'!$A$20,""),IF(AND('Risk Register'!$E$21=3,'Risk Register'!$F$21=3),'Risk Register'!$A$21,""),IF(AND('Risk Register'!$E$22=3,'Risk Register'!$F$22=3),'Risk Register'!$A$22,""),IF(AND('Risk Register'!$E$23=3,'Risk Register'!$F$23=3),'Risk Register'!$A$23,""),IF(AND('Risk Register'!$E$24=3,'Risk Register'!$F$24=3),'Risk Register'!$A$24,""),IF(AND('Risk Register'!$E$25=3,'Risk Register'!$F$25=3),'Risk Register'!$A$25,""),IF(AND('Risk Register'!$E$26=3,'Risk Register'!$F$26=3),'Risk Register'!$A$26,""),IF(AND('Risk Register'!$E$27=3,'Risk Register'!$F$27=3),'Risk Register'!$A$27,""),IF(AND('Risk Register'!$E$28=3,'Risk Register'!$F$28=3),'Risk Register'!$A$28,""),IF(AND('Risk Register'!$E$29=3,'Risk Register'!$F$29=3),'Risk Register'!$A$29,""),IF(AND('Risk Register'!$E$30=3,'Risk Register'!$F$30=3),'Risk Register'!$A$30,""),IF(AND('Risk Register'!$E$31=3,'Risk Register'!$F$31=3),'Risk Register'!$A$31,""),IF(AND('Risk Register'!$E$32=3,'Risk Register'!$F$32=3),'Risk Register'!$A$32,""),IF(AND('Risk Register'!$E$33=3,'Risk Register'!$F$33=3),'Risk Register'!$A$33,""),IF(AND('Risk Register'!$E$34=3,'Risk Register'!$F$34=3),'Risk Register'!$A$34,"")) -> R12, R13 | E6: =_xlfn.TEXTJOIN(", ",TRUE(),IF(AND('Risk Register'!$E$5=3,'Risk Register'!$F$5=4),'Risk Register'!$A$5,""),IF(AND('Risk Register'!$E$6=3,'Risk Register'!$F$6=4),'Risk Register'!$A$6,""),IF(AND('Risk Register'!$E$7=3,'Risk Register'!$F$7=4),'Risk Register'!$A$7,""),IF(AND('Risk Register'!$E$8=3,'Risk Register'!$F$8=4),'Risk Register'!$A$8,""),IF(AND('Risk Register'!$E$9=3,'Risk Register'!$F$9=4),'Risk Register'!$A$9,""),IF(AND('Risk Register'!$E$10=3,'Risk Register'!$F$10=4),'Risk Register'!$A$10,""),IF(AND('Risk Register'!$E$11=3,'Risk Register'!$F$11=4),'Risk Register'!$A$11,""),IF(AND('Risk Register'!$E$12=3,'Risk Register'!$F$12=4),'Risk Register'!$A$12,""),IF(AND('Risk Register'!$E$13=3,'Risk Register'!$F$13=4),'Risk Register'!$A$13,""),IF(AND('Risk Register'!$E$14=3,'Risk Register'!$F$14=4),'Risk Register'!$A$14,""),IF(AND('Risk Register'!$E$15=3,'Risk Register'!$F$15=4),'Risk Register'!$A$15,""),IF(AND('Risk Register'!$E$16=3,'Risk Register'!$F$16=4),'Risk Register'!$A$16,""),IF(AND('Risk Register'!$E$17=3,'Risk Register'!$F$17=4),'Risk Register'!$A$17,""),IF(AND('Risk Register'!$E$18=3,'Risk Register'!$F$18=4),'Risk Register'!$A$18,""),IF(AND('Risk Register'!$E$19=3,'Risk Register'!$F$19=4),'Risk Register'!$A$19,""),IF(AND('Risk Register'!$E$20=3,'Risk Register'!$F$20=4),'Risk Register'!$A$20,""),IF(AND('Risk Register'!$E$21=3,'Risk Register'!$F$21=4),'Risk Register'!$A$21,""),IF(AND('Risk Register'!$E$22=3,'Risk Register'!$F$22=4),'Risk Register'!$A$22,""),IF(AND('Risk Register'!$E$23=3,'Risk Register'!$F$23=4),'Risk Register'!$A$23,""),IF(AND('Risk Register'!$E$24=3,'Risk Register'!$F$24=4),'Risk Register'!$A$24,""),IF(AND('Risk Register'!$E$25=3,'Risk Register'!$F$25=4),'Risk Register'!$A$25,""),IF(AND('Risk Register'!$E$26=3,'Risk Register'!$F$26=4),'Risk Register'!$A$26,""),IF(AND('Risk Register'!$E$27=3,'Risk Register'!$F$27=4),'Risk Register'!$A$27,""),IF(AND('Risk Register'!$E$28=3,'Risk Register'!$F$28=4),'Risk Register'!$A$28,""),IF(AND('Risk Register'!$E$29=3,'Risk Register'!$F$29=4),'Risk Register'!$A$29,""),IF(AND('Risk Register'!$E$30=3,'Risk Register'!$F$30=4),'Risk Register'!$A$30,""),IF(AND('Risk Register'!$E$31=3,'Risk Register'!$F$31=4),'Risk Register'!$A$31,""),IF(AND('Risk Register'!$E$32=3,'Risk Register'!$F$32=4),'Risk Register'!$A$32,""),IF(AND('Risk Register'!$E$33=3,'Risk Register'!$F$33=4),'Risk Register'!$A$33,""),IF(AND('Risk Register'!$E$34=3,'Risk Register'!$F$34=4),'Risk Register'!$A$34,"")) -> R03, R08, R09, R10 | F6: =_xlfn.TEXTJOIN(", ",TRUE(),IF(AND('Risk Register'!$E$5=3,'Risk Register'!$F$5=5),'Risk Register'!$A$5,""),IF(AND('Risk Register'!$E$6=3,'Risk Register'!$F$6=5),'Risk Register'!$A$6,""),IF(AND('Risk Register'!$E$7=3,'Risk Register'!$F$7=5),'Risk Register'!$A$7,""),IF(AND('Risk Register'!$E$8=3,'Risk Register'!$F$8=5),'Risk Register'!$A$8,""),IF(AND('Risk Register'!$E$9=3,'Risk Register'!$F$9=5),'Risk Register'!$A$9,""),IF(AND('Risk Register'!$E$10=3,'Risk Register'!$F$10=5),'Risk Register'!$A$10,""),IF(AND('Risk Register'!$E$11=3,'Risk Register'!$F$11=5),'Risk Register'!$A$11,""),IF(AND('Risk Register'!$E$12=3,'Risk Register'!$F$12=5),'Risk Register'!$A$12,""),IF(AND('Risk Register'!$E$13=3,'Risk Register'!$F$13=5),'Risk Register'!$A$13,""),IF(AND('Risk Register'!$E$14=3,'Risk Register'!$F$14=5),'Risk Register'!$A$14,""),IF(AND('Risk Register'!$E$15=3,'Risk Register'!$F$15=5),'Risk Register'!$A$15,""),IF(AND('Risk Register'!$E$16=3,'Risk Register'!$F$16=5),'Risk Register'!$A$16,""),IF(AND('Risk Register'!$E$17=3,'Risk Register'!$F$17=5),'Risk Register'!$A$17,""),IF(AND('Risk Register'!$E$18=3,'Risk Register'!$F$18=5),'Risk Register'!$A$18,""),IF(AND('Risk Register'!$E$19=3,'Risk Register'!$F$19=5),'Risk Register'!$A$19,""),IF(AND('Risk Register'!$E$20=3,'Risk Register'!$F$20=5),'Risk Register'!$A$20,""),IF(AND('Risk Register'!$E$21=3,'Risk Register'!$F$21=5),'Risk Register'!$A$21,""),IF(AND('Risk Register'!$E$22=3,'Risk Register'!$F$22=5),'Risk Register'!$A$22,""),IF(AND('Risk Register'!$E$23=3,'Risk Register'!$F$23=5),'Risk Register'!$A$23,""),IF(AND('Risk Register'!$E$24=3,'Risk Register'!$F$24=5),'Risk Register'!$A$24,""),IF(AND('Risk Register'!$E$25=3,'Risk Register'!$F$25=5),'Risk Register'!$A$25,""),IF(AND('Risk Register'!$E$26=3,'Risk Register'!$F$26=5),'Risk Register'!$A$26,""),IF(AND('Risk Register'!$E$27=3,'Risk Register'!$F$27=5),'Risk Register'!$A$27,""),IF(AND('Risk Register'!$E$28=3,'Risk Register'!$F$28=5),'Risk Register'!$A$28,""),IF(AND('Risk Register'!$E$29=3,'Risk Register'!$F$29=5),'Risk Register'!$A$29,""),IF(AND('Risk Register'!$E$30=3,'Risk Register'!$F$30=5),'Risk Register'!$A$30,""),IF(AND('Risk Register'!$E$31=3,'Risk Register'!$F$31=5),'Risk Register'!$A$31,""),IF(AND('Risk Register'!$E$32=3,'Risk Register'!$F$32=5),'Risk Register'!$A$32,""),IF(AND('Risk Register'!$E$33=3,'Risk Register'!$F$33=5),'Risk Register'!$A$33,""),IF(AND('Risk Register'!$E$34=3,'Risk Register'!$F$34=5),'Risk Register'!$A$34,"")) -> R02
A7: 2 Aşağı | B7: =_xlfn.TEXTJOIN(", ",TRUE(),IF(AND('Risk Register'!$E$5=2,'Risk Register'!$F$5=1),'Risk Register'!$A$5,""),IF(AND('Risk Register'!$E$6=2,'Risk Register'!$F$6=1),'Risk Register'!$A$6,""),IF(AND('Risk Register'!$E$7=2,'Risk Register'!$F$7=1),'Risk Register'!$A$7,""),IF(AND('Risk Register'!$E$8=2,'Risk Register'!$F$8=1),'Risk Register'!$A$8,""),IF(AND('Risk Register'!$E$9=2,'Risk Register'!$F$9=1),'Risk Register'!$A$9,""),IF(AND('Risk Register'!$E$10=2,'Risk Register'!$F$10=1),'Risk Register'!$A$10,""),IF(AND('Risk Register'!$E$11=2,'Risk Register'!$F$11=1),'Risk Register'!$A$11,""),IF(AND('Risk Register'!$E$12=2,'Risk Register'!$F$12=1),'Risk Register'!$A$12,""),IF(AND('Risk Register'!$E$13=2,'Risk Register'!$F$13=1),'Risk Register'!$A$13,""),IF(AND('Risk Register'!$E$14=2,'Risk Register'!$F$14=1),'Risk Register'!$A$14,""),IF(AND('Risk Register'!$E$15=2,'Risk Register'!$F$15=1),'Risk Register'!$A$15,""),IF(AND('Risk Register'!$E$16=2,'Risk Register'!$F$16=1),'Risk Register'!$A$16,""),IF(AND('Risk Register'!$E$17=2,'Risk Register'!$F$17=1),'Risk Register'!$A$17,""),IF(AND('Risk Register'!$E$18=2,'Risk Register'!$F$18=1),'Risk Register'!$A$18,""),IF(AND('Risk Register'!$E$19=2,'Risk Register'!$F$19=1),'Risk Register'!$A$19,""),IF(AND('Risk Register'!$E$20=2,'Risk Register'!$F$20=1),'Risk Register'!$A$20,""),IF(AND('Risk Register'!$E$21=2,'Risk Register'!$F$21=1),'Risk Register'!$A$21,""),IF(AND('Risk Register'!$E$22=2,'Risk Register'!$F$22=1),'Risk Register'!$A$22,""),IF(AND('Risk Register'!$E$23=2,'Risk Register'!$F$23=1),'Risk Register'!$A$23,""),IF(AND('Risk Register'!$E$24=2,'Risk Register'!$F$24=1),'Risk Register'!$A$24,""),IF(AND('Risk Register'!$E$25=2,'Risk Register'!$F$25=1),'Risk Register'!$A$25,""),IF(AND('Risk Register'!$E$26=2,'Risk Register'!$F$26=1),'Risk Register'!$A$26,""),IF(AND('Risk Register'!$E$27=2,'Risk Register'!$F$27=1),'Risk Register'!$A$27,""),IF(AND('Risk Register'!$E$28=2,'Risk Register'!$F$28=1),'Risk Register'!$A$28,""),IF(AND('Risk Register'!$E$29=2,'Risk Register'!$F$29=1),'Risk Register'!$A$29,""),IF(AND('Risk Register'!$E$30=2,'Risk Register'!$F$30=1),'Risk Register'!$A$30,""),IF(AND('Risk Register'!$E$31=2,'Risk Register'!$F$31=1),'Risk Register'!$A$31,""),IF(AND('Risk Register'!$E$32=2,'Risk Register'!$F$32=1),'Risk Register'!$A$32,""),IF(AND('Risk Register'!$E$33=2,'Risk Register'!$F$33=1),'Risk Register'!$A$33,""),IF(AND('Risk Register'!$E$34=2,'Risk Register'!$F$34=1),'Risk Register'!$A$34,"")) | C7: =_xlfn.TEXTJOIN(", ",TRUE(),IF(AND('Risk Register'!$E$5=2,'Risk Register'!$F$5=2),'Risk Register'!$A$5,""),IF(AND('Risk Register'!$E$6=2,'Risk Register'!$F$6=2),'Risk Register'!$A$6,""),IF(AND('Risk Register'!$E$7=2,'Risk Register'!$F$7=2),'Risk Register'!$A$7,""),IF(AND('Risk Register'!$E$8=2,'Risk Register'!$F$8=2),'Risk Register'!$A$8,""),IF(AND('Risk Register'!$E$9=2,'Risk Register'!$F$9=2),'Risk Register'!$A$9,""),IF(AND('Risk Register'!$E$10=2,'Risk Register'!$F$10=2),'Risk Register'!$A$10,""),IF(AND('Risk Register'!$E$11=2,'Risk Register'!$F$11=2),'Risk Register'!$A$11,""),IF(AND('Risk Register'!$E$12=2,'Risk Register'!$F$12=2),'Risk Register'!$A$12,""),IF(AND('Risk Register'!$E$13=2,'Risk Register'!$F$13=2),'Risk Register'!$A$13,""),IF(AND('Risk Register'!$E$14=2,'Risk Register'!$F$14=2),'Risk Register'!$A$14,""),IF(AND('Risk Register'!$E$15=2,'Risk Register'!$F$15=2),'Risk Register'!$A$15,""),IF(AND('Risk Register'!$E$16=2,'Risk Register'!$F$16=2),'Risk Register'!$A$16,""),IF(AND('Risk Register'!$E$17=2,'Risk Register'!$F$17=2),'Risk Register'!$A$17,""),IF(AND('Risk Register'!$E$18=2,'Risk Register'!$F$18=2),'Risk Register'!$A$18,""),IF(AND('Risk Register'!$E$19=2,'Risk Register'!$F$19=2),'Risk Register'!$A$19,""),IF(AND('Risk Register'!$E$20=2,'Risk Register'!$F$20=2),'Risk Register'!$A$20,""),IF(AND('Risk Register'!$E$21=2,'Risk Register'!$F$21=2),'Risk Register'!$A$21,""),IF(AND('Risk Register'!$E$22=2,'Risk Register'!$F$22=2),'Risk Register'!$A$22,""),IF(AND('Risk Register'!$E$23=2,'Risk Register'!$F$23=2),'Risk Register'!$A$23,""),IF(AND('Risk Register'!$E$24=2,'Risk Register'!$F$24=2),'Risk Register'!$A$24,""),IF(AND('Risk Register'!$E$25=2,'Risk Register'!$F$25=2),'Risk Register'!$A$25,""),IF(AND('Risk Register'!$E$26=2,'Risk Register'!$F$26=2),'Risk Register'!$A$26,""),IF(AND('Risk Register'!$E$27=2,'Risk Register'!$F$27=2),'Risk Register'!$A$27,""),IF(AND('Risk Register'!$E$28=2,'Risk Register'!$F$28=2),'Risk Register'!$A$28,""),IF(AND('Risk Register'!$E$29=2,'Risk Register'!$F$29=2),'Risk Register'!$A$29,""),IF(AND('Risk Register'!$E$30=2,'Risk Register'!$F$30=2),'Risk Register'!$A$30,""),IF(AND('Risk Register'!$E$31=2,'Risk Register'!$F$31=2),'Risk Register'!$A$31,""),IF(AND('Risk Register'!$E$32=2,'Risk Register'!$F$32=2),'Risk Register'!$A$32,""),IF(AND('Risk Register'!$E$33=2,'Risk Register'!$F$33=2),'Risk Register'!$A$33,""),IF(AND('Risk Register'!$E$34=2,'Risk Register'!$F$34=2),'Risk Register'!$A$34,"")) | D7: =_xlfn.TEXTJOIN(", ",TRUE(),IF(AND('Risk Register'!$E$5=2,'Risk Register'!$F$5=3),'Risk Register'!$A$5,""),IF(AND('Risk Register'!$E$6=2,'Risk Register'!$F$6=3),'Risk Register'!$A$6,""),IF(AND('Risk Register'!$E$7=2,'Risk Register'!$F$7=3),'Risk Register'!$A$7,""),IF(AND('Risk Register'!$E$8=2,'Risk Register'!$F$8=3),'Risk Register'!$A$8,""),IF(AND('Risk Register'!$E$9=2,'Risk Register'!$F$9=3),'Risk Register'!$A$9,""),IF(AND('Risk Register'!$E$10=2,'Risk Register'!$F$10=3),'Risk Register'!$A$10,""),IF(AND('Risk Register'!$E$11=2,'Risk Register'!$F$11=3),'Risk Register'!$A$11,""),IF(AND('Risk Register'!$E$12=2,'Risk Register'!$F$12=3),'Risk Register'!$A$12,""),IF(AND('Risk Register'!$E$13=2,'Risk Register'!$F$13=3),'Risk Register'!$A$13,""),IF(AND('Risk Register'!$E$14=2,'Risk Register'!$F$14=3),'Risk Register'!$A$14,""),IF(AND('Risk Register'!$E$15=2,'Risk Register'!$F$15=3),'Risk Register'!$A$15,""),IF(AND('Risk Register'!$E$16=2,'Risk Register'!$F$16=3),'Risk Register'!$A$16,""),IF(AND('Risk Register'!$E$17=2,'Risk Register'!$F$17=3),'Risk Register'!$A$17,""),IF(AND('Risk Register'!$E$18=2,'Risk Register'!$F$18=3),'Risk Register'!$A$18,""),IF(AND('Risk Register'!$E$19=2,'Risk Register'!$F$19=3),'Risk Register'!$A$19,""),IF(AND('Risk Register'!$E$20=2,'Risk Register'!$F$20=3),'Risk Register'!$A$20,""),IF(AND('Risk Register'!$E$21=2,'Risk Register'!$F$21=3),'Risk Register'!$A$21,""),IF(AND('Risk Register'!$E$22=2,'Risk Register'!$F$22=3),'Risk Register'!$A$22,""),IF(AND('Risk Register'!$E$23=2,'Risk Register'!$F$23=3),'Risk Register'!$A$23,""),IF(AND('Risk Register'!$E$24=2,'Risk Register'!$F$24=3),'Risk Register'!$A$24,""),IF(AND('Risk Register'!$E$25=2,'Risk Register'!$F$25=3),'Risk Register'!$A$25,""),IF(AND('Risk Register'!$E$26=2,'Risk Register'!$F$26=3),'Risk Register'!$A$26,""),IF(AND('Risk Register'!$E$27=2,'Risk Register'!$F$27=3),'Risk Register'!$A$27,""),IF(AND('Risk Register'!$E$28=2,'Risk Register'!$F$28=3),'Risk Register'!$A$28,""),IF(AND('Risk Register'!$E$29=2,'Risk Register'!$F$29=3),'Risk Register'!$A$29,""),IF(AND('Risk Register'!$E$30=2,'Risk Register'!$F$30=3),'Risk Register'!$A$30,""),IF(AND('Risk Register'!$E$31=2,'Risk Register'!$F$31=3),'Risk Register'!$A$31,""),IF(AND('Risk Register'!$E$32=2,'Risk Register'!$F$32=3),'Risk Register'!$A$32,""),IF(AND('Risk Register'!$E$33=2,'Risk Register'!$F$33=3),'Risk Register'!$A$33,""),IF(AND('Risk Register'!$E$34=2,'Risk Register'!$F$34=3),'Risk Register'!$A$34,"")) -> R15 | E7: =_xlfn.TEXTJOIN(", ",TRUE(),IF(AND('Risk Register'!$E$5=2,'Risk Register'!$F$5=4),'Risk Register'!$A$5,""),IF(AND('Risk Register'!$E$6=2,'Risk Register'!$F$6=4),'Risk Register'!$A$6,""),IF(AND('Risk Register'!$E$7=2,'Risk Register'!$F$7=4),'Risk Register'!$A$7,""),IF(AND('Risk Register'!$E$8=2,'Risk Register'!$F$8=4),'Risk Register'!$A$8,""),IF(AND('Risk Register'!$E$9=2,'Risk Register'!$F$9=4),'Risk Register'!$A$9,""),IF(AND('Risk Register'!$E$10=2,'Risk Register'!$F$10=4),'Risk Register'!$A$10,""),IF(AND('Risk Register'!$E$11=2,'Risk Register'!$F$11=4),'Risk Register'!$A$11,""),IF(AND('Risk Register'!$E$12=2,'Risk Register'!$F$12=4),'Risk Register'!$A$12,""),IF(AND('Risk Register'!$E$13=2,'Risk Register'!$F$13=4),'Risk Register'!$A$13,""),IF(AND('Risk Register'!$E$14=2,'Risk Register'!$F$14=4),'Risk Register'!$A$14,""),IF(AND('Risk Register'!$E$15=2,'Risk Register'!$F$15=4),'Risk Register'!$A$15,""),IF(AND('Risk Register'!$E$16=2,'Risk Register'!$F$16=4),'Risk Register'!$A$16,""),IF(AND('Risk Register'!$E$17=2,'Risk Register'!$F$17=4),'Risk Register'!$A$17,""),IF(AND('Risk Register'!$E$18=2,'Risk Register'!$F$18=4),'Risk Register'!$A$18,""),IF(AND('Risk Register'!$E$19=2,'Risk Register'!$F$19=4),'Risk Register'!$A$19,""),IF(AND('Risk Register'!$E$20=2,'Risk Register'!$F$20=4),'Risk Register'!$A$20,""),IF(AND('Risk Register'!$E$21=2,'Risk Register'!$F$21=4),'Risk Register'!$A$21,""),IF(AND('Risk Register'!$E$22=2,'Risk Register'!$F$22=4),'Risk Register'!$A$22,""),IF(AND('Risk Register'!$E$23=2,'Risk Register'!$F$23=4),'Risk Register'!$A$23,""),IF(AND('Risk Register'!$E$24=2,'Risk Register'!$F$24=4),'Risk Register'!$A$24,""),IF(AND('Risk Register'!$E$25=2,'Risk Register'!$F$25=4),'Risk Register'!$A$25,""),IF(AND('Risk Register'!$E$26=2,'Risk Register'!$F$26=4),'Risk Register'!$A$26,""),IF(AND('Risk Register'!$E$27=2,'Risk Register'!$F$27=4),'Risk Register'!$A$27,""),IF(AND('Risk Register'!$E$28=2,'Risk Register'!$F$28=4),'Risk Register'!$A$28,""),IF(AND('Risk Register'!$E$29=2,'Risk Register'!$F$29=4),'Risk Register'!$A$29,""),IF(AND('Risk Register'!$E$30=2,'Risk Register'!$F$30=4),'Risk Register'!$A$30,""),IF(AND('Risk Register'!$E$31=2,'Risk Register'!$F$31=4),'Risk Register'!$A$31,""),IF(AND('Risk Register'!$E$32=2,'Risk Register'!$F$32=4),'Risk Register'!$A$32,""),IF(AND('Risk Register'!$E$33=2,'Risk Register'!$F$33=4),'Risk Register'!$A$33,""),IF(AND('Risk Register'!$E$34=2,'Risk Register'!$F$34=4),'Risk Register'!$A$34,"")) -> R11, R14 | F7: =_xlfn.TEXTJOIN(", ",TRUE(),IF(AND('Risk Register'!$E$5=2,'Risk Register'!$F$5=5),'Risk Register'!$A$5,""),IF(AND('Risk Register'!$E$6=2,'Risk Register'!$F$6=5),'Risk Register'!$A$6,""),IF(AND('Risk Register'!$E$7=2,'Risk Register'!$F$7=5),'Risk Register'!$A$7,""),IF(AND('Risk Register'!$E$8=2,'Risk Register'!$F$8=5),'Risk Register'!$A$8,""),IF(AND('Risk Register'!$E$9=2,'Risk Register'!$F$9=5),'Risk Register'!$A$9,""),IF(AND('Risk Register'!$E$10=2,'Risk Register'!$F$10=5),'Risk Register'!$A$10,""),IF(AND('Risk Register'!$E$11=2,'Risk Register'!$F$11=5),'Risk Register'!$A$11,""),IF(AND('Risk Register'!$E$12=2,'Risk Register'!$F$12=5),'Risk Register'!$A$12,""),IF(AND('Risk Register'!$E$13=2,'Risk Register'!$F$13=5),'Risk Register'!$A$13,""),IF(AND('Risk Register'!$E$14=2,'Risk Register'!$F$14=5),'Risk Register'!$A$14,""),IF(AND('Risk Register'!$E$15=2,'Risk Register'!$F$15=5),'Risk Register'!$A$15,""),IF(AND('Risk Register'!$E$16=2,'Risk Register'!$F$16=5),'Risk Register'!$A$16,""),IF(AND('Risk Register'!$E$17=2,'Risk Register'!$F$17=5),'Risk Register'!$A$17,""),IF(AND('Risk Register'!$E$18=2,'Risk Register'!$F$18=5),'Risk Register'!$A$18,""),IF(AND('Risk Register'!$E$19=2,'Risk Register'!$F$19=5),'Risk Register'!$A$19,""),IF(AND('Risk Register'!$E$20=2,'Risk Register'!$F$20=5),'Risk Register'!$A$20,""),IF(AND('Risk Register'!$E$21=2,'Risk Register'!$F$21=5),'Risk Register'!$A$21,""),IF(AND('Risk Register'!$E$22=2,'Risk Register'!$F$22=5),'Risk Register'!$A$22,""),IF(AND('Risk Register'!$E$23=2,'Risk Register'!$F$23=5),'Risk Register'!$A$23,""),IF(AND('Risk Register'!$E$24=2,'Risk Register'!$F$24=5),'Risk Register'!$A$24,""),IF(AND('Risk Register'!$E$25=2,'Risk Register'!$F$25=5),'Risk Register'!$A$25,""),IF(AND('Risk Register'!$E$26=2,'Risk Register'!$F$26=5),'Risk Register'!$A$26,""),IF(AND('Risk Register'!$E$27=2,'Risk Register'!$F$27=5),'Risk Register'!$A$27,""),IF(AND('Risk Register'!$E$28=2,'Risk Register'!$F$28=5),'Risk Register'!$A$28,""),IF(AND('Risk Register'!$E$29=2,'Risk Register'!$F$29=5),'Risk Register'!$A$29,""),IF(AND('Risk Register'!$E$30=2,'Risk Register'!$F$30=5),'Risk Register'!$A$30,""),IF(AND('Risk Register'!$E$31=2,'Risk Register'!$F$31=5),'Risk Register'!$A$31,""),IF(AND('Risk Register'!$E$32=2,'Risk Register'!$F$32=5),'Risk Register'!$A$32,""),IF(AND('Risk Register'!$E$33=2,'Risk Register'!$F$33=5),'Risk Register'!$A$33,""),IF(AND('Risk Register'!$E$34=2,'Risk Register'!$F$34=5),'Risk Register'!$A$34,"")) -> R07
